Workbook

Sheet Portada
A2: ANÁLISIS TÉCNICO-ECONÓMICO
A3: CELDA ROBÓTICA DE PALETIZADO
A4: Línea de Producción de Bebidas — Coca-Cola & Monster Energy
B6: Proyecto: | C6: Automatización — Celda Robótica de Paletizado
B7: Productos: | C7: Coca-Cola Retornable 1.5 L | Coca-Cola Plástica 2.5 L | Monster Energy 500 mL
B8: Líneas: | C8: Línea 1: Coca-Cola (Retornable + Plástica) — Línea 2: Monster (3 turnos)
B9: Capacidad/día: | C9: Retornable: 19 800 un/día (1 turno) | Plástica: 115 184 un/día (2 turnos) | Monster: 129 550 un/día (3 turnos)
B10: Entidad: | C10: Automatización de Procesos de Manufactura 2026-1S
B11: Fecha: | C11: Marzo 2026
B12: Moneda: | C12: Pesos Colombianos (COP) | TRM referencia: $ 3723,05 COP/USD
B13: Horizonte: | C13: 10 años
A15: RESUMEN DE INDICADORES FINANCIEROS CLAVE
B16: CAPEX Total | C16: OPEX Anual | D16: Beneficios Brutos | E16: Flujo Neto Anual | F16: VPN (10 años) | G16: TIR | H16: Payback
B17: =CAPEX!H70 -> 1.9041443e+09 | C17: =OPEX_Beneficios!C11 -> 171120839 | D17: =OPEX_Beneficios!C22 -> 6.0692062e+08 | E17: =OPEX_Beneficios!C23 -> 4.3579978e+08 | F17: =Indicadores!D5 -> 1.1756237e+09 | G17: =Indicadores!D6 -> 0.24504193 | H17: =Indicadores!D7 -> 4.3693099

Sheet Supuestos
B1: SUPUESTOS Y PARÁMETROS DEL MODELO
B3: PRODUCCIÓN DIARIA (Base Simulación)
B4: Parámetro | C4: Valor | D4: Unidad | E4: Nota / Fuente
B5: Coca-Cola Retornable 1.5 L | C5: 19800 | D5: un/día | E5: 1 turno/día
B6: Coca-Cola Plástica 2.5 L | C6: 115184 | D6: un/día | E6: 2 turnos/día
B7: Monster Energy 500 mL | C7: 129550 | D7: un/día | E7: 3 turnos/día
B8: Días laborables / año | C8: 365 | D8: días | E8: Operación continua
B10: PARÁMETROS ECONÓMICOS
B11: Parámetro | C11: Valor | D11: Unidad | E11: Nota / Fuente
B12: TRM referencia | C12: 3723.05 | D12: COP/USD | E12: 24/03/2026
B13: Tasa de descuento (WACC) | C13: 0.12 | E13: Incluye prima de riesgo Colombia
B14: Inflación anual esperada | C14: 0.05 | E14: Meta BanRep promedio
B15: Crecimiento demanda bebidas/año | C15: 0.03 | E15: Proyección sector bebidas Colombia
B17: PARÁMETROS DE MANO DE OBRA
B18: Parámetro | C18: Valor | D18: Unidad | E18: Nota / Fuente
B19: Salario mensual operador base | C19: 1750905 | D19: COP/mes | E19: SMV 2026 — Decreto 2671 de 2025
B20: Factor prestaciones sociales | C20: 1.52 | E20: Vacaciones, cesantías, EPS, ARL, etc.
B21: Salario + prestaciones operador | C21: =C19*C20 -> 2661375.6 | D21: COP/mes | E21: Costo real por trabajador
B22: Operadores paletizado (antes) | C22: 10 | D22: operadores | E22: 2 por celda × 2 líneas × ~2.5 turnos
B23: Operadores remanentes (después) | C23: 2 | D23: operadores | E23: Supervisores / apoyo
B24: Operadores suprimidos | C24: =C22-C23 -> 8 | D24: operadores
B26: PARÁMETROS DE ENERGÍA
B27: Parámetro | C27: Valor | D27: Unidad | E27: Nota / Fuente
B28: Potencia robot Línea 1 (Coca-Cola) | C28: 3.5 | D28: kW | E28: ABB IRB 660 — dato técnico
B29: Potencia robot Línea 2 (Monster) | C29: 2 | D29: kW | E29: ABB IRB 460 — menor consumo que IRB 660
B30: Potencia conveyors y auxiliares | C30: 2.5 | D30: kW | E30: Transportadores + actuadores
B31: Horas operación promedio / día | C31: 20 | D31: h | E31: Promedio ponderado 3 líneas
B32: Tarifa energía eléctrica industrial | C32: 600 | D32: COP/kWh | E32: Tarifa industrial media Colombia 2026
B33: Potencia adicional Clearpack + Stretch wrapper | C33: 13.5 | D33: kW | E33: Clearpack EFK250L: ~12 kW (sealer+túnel) + Robopac: ~1,5 kW
B34: PARÁMETROS DE PALETIZADO
B35: Parámetro | C35: Valor | D35: Unidad | E35: Nota / Fuente
B36: Unidades / paca Coca-Cola Ret. | C36: 6 | D36: un/caja | E36: paca retornable estándar
B37: Unidades / paca Coca-Cola Plás. | C37: 6 | D37: un/caja | E37: paca 6×2.5 L
B38: Unidades / caja Monster | C38: 24 | D38: un/caja | E38: Caja estándar latas
B39: Capas / pallet Coca-Cola | C39: 8 | D39: capas
B40: Capas / pallet Monster | C40: 10 | D40: capas
B41: Pacas / capa Coca-Cola | C41: 9 | D41: cajas
B42: Pacas / capa Monster | C42: 12 | D42: cajas
B44: PARÁMETROS DE EMPAQUE (Línea Monster — Clearpack EFK250L)
B45: Parámetro | C45: Valor | D45: Unidad | E45: Nota / Fuente
...

Sheet CAPEX
B1: CAPEX — INVERSIÓN INICIAL | CELDA ROBÓTICA DE PALETIZADO
B2: Ítem | C2: Concepto | D2: Cant. | E2: Unid. | F2: P. Unit. Base (COP) | G2: Arancel + Ship. (COP) | H2: Total (COP) | I2: Ref. USD (unit.) | J2: Enlace / Fuente
B3: 1. ROBOTS INDUSTRIALES Y CONTROLADORES
B4: 1.1 | C4: Robot ABB IRB 660-3.15/250 — Línea 1 (Coca-Cola) Robot paletizador 4 ejes, alcance 3,15 m, carga máx. 250 kg. | D4: 1 | E4: und | F4: 230829100 | G4: =ROUND(F4*0.1,0) -> 23082910 | H4: =D4*(F4+G4) -> 253912010 | I4: ~62 000 USD | J4: https://new.abb.com/products/robotics/robots/palletizing-robots/irb-660
B5: 1.2 | C5: Robot ABB IRB 460-2.40/110 — Línea 2 (Monster) Robot paletizador 4 ejes, alcance 2,40 m, carga máx. 110 kg. | D5: 1 | E5: und | F5: 141475900 | G5: =ROUND(F5*0.1,0) -> 14147590 | H5: =D5*(F5+G5) -> 155623490 | I5: ~38 000 USD | J5: https://new.abb.com/products/robotics/robots/palletizing-robots/irb-460
B6: 1.3 | C6: Controlador IRC5 — ABB Incluye FlexPendant táctil, módulo de movimiento y armario estándar. | D6: 2 | E6: und | F6: 46538125 | G6: =ROUND(F6*0.1,0) -> 4653813 | H6: =D6*(F6+G6) -> 102383876 | I6: ~12 500 USD | J6: https://new.abb.com/products/robotics/controllers/irc5
B7: 2. HERRAMIENTAS DE AGARRE (EOAT) Y SISTEMAS NEUMÁTICOS
B8: Línea 1 — Coca-Cola (Retornable 1.5 L + Plástica 2.5 L): Clamp Gripper Neumático
B9: 2.1 | C9: EOAT L1: Clamp gripper neumático para cajas Coca-Cola Accionamiento neumático con mordazas paralelas y superficies antideslizantes. | D9: 1 | E9: und | F9: 33507450 | G9: =ROUND(F9*0.1,0) -> 3350745 | H9: =D9*(F9+G9) -> 36858195 | I9: ~9 000 USD | J9: https://schunk.com/co_es/productos/sujecion/
B10: 2.2 | C10: Unidad FRL (filtro-regulador-lubricador) L1 | D10: 1 | E10: und | F10: 6701490 | G10: =ROUND(F10*0.1,0) -> 670149 | H10: =D10*(F10+G10) -> 7371639 | I10: ~1 800 USD | J10: https://www.festo.com/co/es/
B11: 2.3 | C11: Válvulas distribuidoras 5/2 doble solenoide L1 — Festo | D11: 2 | E11: und | F11: 2233830 | G11: =ROUND(F11*0.1,0) -> 223383 | H11: =D11*(F11+G11) -> 4914426 | I11: ~600 USD c/u | J11: https://www.festo.com/co/es/
B12: 2.4 | C12: Tuberías, racores y accesorios neumáticos L1 | D12: 1 | E12: global | F12: 4467660 | G12: =ROUND(F12*0.1,0) -> 446766 | H12: =D12*(F12+G12) -> 4914426 | I12: ~1 200 USD | J12: https://www.festo.com/co/es/
B13: 2.5 | C13: Sensor de presión neumática L1 Verificación de agarre efectivo antes del traslado. | D13: 2 | E13: und | F13: 1489220 | G13: =ROUND(F13*0.1,0) -> 148922 | H13: =D13*(F13+G13) -> 3276284 | I13: ~400 USD c/u | J13: https://www.festo.com/co/es/
B14: Línea 2 — Monster Energy (Cajas de 24 latas): Clamp Gripper Neumático
B15: 2.6 | C15: EOAT L2: Clamp gripper neumático para cajas Monster (24 latas) Accionamiento neumático con mordazas paralelas dimensionadas para cajas de cartón. | D15: 1 | E15: und | F15: 18615250 | G15: =ROUND(F15*0.1,0) -> 1861525 | H15: =D15*(F15+G15) -> 20476775 | I15: ~5 000 USD | J15: https://schunk.com/co_es/productos/sujecion/
B16: 2.7 | C16: Unidad FRL (filtro-regulador-lubricador) L2 | D16: 1 | E16: und | F16: 4467660 | G16: =ROUND(F16*0.1,0) -> 446766 | H16: =D16*(F16+G16) -> 4914426 | I16: ~1 200 USD | J16: https://www.festo.com/co/es/
B17: 2.8 | C17: Válvulas distribuidoras 5/2 doble solenoide L2 — Festo | D17: 2 | E17: und | F17: 2233830 | G17: =ROUND(F17*0.1,0) -> 223383 | H17: =D17*(F17+G17) -> 4914426 | I17: ~600 USD c/u | J17: https://www.festo.com/co/es/
B18: 2.9 | C18: Tuberías, racores y accesorios neumáticos L2 | D18: 1 | E18: global | F18: 2978440 | G18: =ROUND(F18*0.1,0) -> 297844 | H18: =D18*(F18+G18) -> 3276284 | I18: ~800 USD | J18: https://www.festo.com/co/es/
B19: 2.10 | C19: Sensor de presión neumática L2 Verificación de agarre efectivo del clamp gripper. | D19: 2 | E19: und | F19: 1489220 | G19: =ROUND(F19*0.1,0) -> 148922 | H19: =D19*(F19+G19) -> 3276284 | I19: ~400 USD c/u | J19: https://www.festo.com/co/es/
B20: 3. SISTEMA DE CONTROL ELÉCTRICO E INDUSTRIAL (por línea × 2)
B21: 3.1 | C21: PLC Allen-Bradley ControlLogix 5580 — chasis 8 ranuras (1756-L83E) Procesador 40 ns/instrucción, 3 MB mem. usuario, EtherNet/IP integrado. | D21: 2 | E21: und | F21: 29784400 | G21: =ROUND(F21*0.1,0) -> 2978440 | H21: =D21*(F21+G21) -> 65525680 | I21: ~8 000 USD | J21: https://www.rockwellautomation.com/es-CO/products/hardware/allen-bradley/logix/controllogix-family.html
B22: 3.2 | C22: Fuente de alimentación 24 VDC – 10 A (1756-PA75R) | D22: 2 | E22: und | F22: 2047678 | G22: =ROUND(F22*0.1,0) -> 204768 | H22: =D22*(F22+G22) -> 4504892 | I22: ~550 USD | J22: https://www.rockwellautomation.com/
B23: 3.3 | C23: Módulo entradas digitales 16 ch – 24 VDC (1756-IB16D) Sensores posición, finales de carrera, botones de operador. | D23: 4 | E23: und | F23: 1563681 | G23: =ROUND(F23*0.1,0) -> 156368 | H23: =D23*(F23+G23) -> 6880196 | I23: ~420 USD | J23: https://www.rockwellautomation.com/
B24: 3.4 | C24: Módulo salidas digitales 16 ch – 24 VDC (1756-OB16D) Actuadores, solenoides neumáticos, semáforos de seguridad. | D24: 4 | E24: und | F24: 1563681 | G24: =ROUND(F24*0.1,0) -> 156368 | H24: =D24*(F24+G24) -> 6880196 | I24: ~420 USD | J24: https://www.rockwellautomation.com/
B25: 3.5 | C25: Módulo entradas analógicas 8 ch – ±10 V / 4-20 mA (1756-IF8) Sensores de presión neumática y celdas de carga. | D25: 2 | E25: und | F25: 2419982 | G25: =ROUND(F25*0.1,0) -> 241998 | H25: =D25*(F25+G25) -> 5323960 | I25: ~650 USD | J25: https://www.rockwellautomation.com/
B26: 3.6 | C26: HMI PanelView Plus 7 – 10" touch color (2711P-T10C22D9P) Interfaz operador local por celda. Integración FactoryTalk View. | D26: 2 | E26: und | F26: 13030675 | G26: =ROUND(F26*0.1,0) -> 1303068 | H26: =D26*(F26+G26) -> 28667486 | I26: ~3 500 USD | J26: https://www.rockwellautomation.com/
B27: 3.7 | C27: Switch EtherNet/IP industrial 8 puertos (1783-US8T) Red de comunicaciones PLC ↔ Robot ↔ SCADA. | D27: 2 | E27: und | F27: 3350745 | G27: =ROUND(F27*0.1,0) -> 335075 | H27: =D27*(F27+G27) -> 7371640 | I27: ~900 USD | J27: https://www.rockwellautomation.com/
B28: 3.8 | C28: Breaker principal trifásico 3P – 60 A (Schneider NSX160B) | D28: 2 | E28: und | F28: 1303068 | G28: =ROUND(F28*0.1,0) -> 130307 | H28: =D28*(F28+G28) -> 2866750 | I28: ~350 USD | J28: https://www.se.com/co/es/
B29: 3.9 | C29: Interruptores termomagnéticos 2P – 20 A (ramales internos) Protección individual robot, HMI, ventilación y circuitos 24 VDC. | D29: 8 | E29: und | F29: 223383 | G29: =ROUND(F29*0.1,0) -> 22338 | H29: =D29*(F29+G29) -> 1965768 | I29: ~60 USD c/u | J29: https://www.se.com/co/es/
B30: 3.10 | C30: Gabinete eléctrico NEMA 4 / IP54 – 1 200×800×300 mm (RAL 7035) Chapa 14 AWG, ventilación forzada con filtro, cerradura. | D30: 2 | E30: und | F30: 10424540 | G30: =ROUND(F30*0.1,0) -> 1042454 | H30: =D30*(F30+G30) -> 22933988 | I30: ~2 800 USD | J30: https://www.rittal.com/co-es/
B31: 3.11 | C31: Canaleta ranurada, riel DIN, borneras y accesorios de montaje Canaleta 60×40 mm, riel C 35 mm, borneras 2,5 mm², etiquetas. | D31: 1 | E31: global | F31: 5584575 | G31: =ROUND(F31*0.1,0) -> 558458 | H31: =D31*(F31+G31) -> 6143033 | I31: ~1 500 USD | J31: https://www.wago.com/co/
B32: 3.12 | C32: Cableado de fuerza y control — cable, tubería EMT y bandejas Cable 4×4 mm² fuerza robot, AWG 16 control, conduit EMT ½" y ¾". | D32: 1 | E32: global | F32: 16753725 | G32: =ROUND(F32*0.1,0) -> 1675373 | H32: =D32*(F32+G32) -> 18429098 | I32: ~4 500 USD | J32: Contratista eléctrico especializado
B33: 4. SISTEMAS AUXILIARES, TRANSPORTE Y ENVOLTURA
B34: 4.1 | C34: Conveyor de entrada de cajas — Línea 1 (Coca-Cola) Conveyor de rodillos accionado, longitud ~10 m, velocidad 0,3 m/s. | D34: 1 | E34: sistema | F34: 37230500 | G34: =ROUND(F34*0.1,0) -> 3723050 | H34: =D34*(F34+G34) -> 40953550 | I34: ~10 000 USD | J34: https://www.interroll.com/es/
B35: 4.2 | C35: Conveyor de entrada de cajas — Línea 2 (Monster) Conveyor de banda plana, longitud ~10 m. | D35: 1 | E35: sistema | F35: 29784400 | G35: =ROUND(F35*0.1,0) -> 2978440 | H35: =D35*(F35+G35) -> 32762840 | I35: ~8 000 USD | J35: https://www.interroll.com/es/
B36: 4.3 | C36: Conveyor de triple cadena — salida de palets cargados L1 Cadenas reforzadas 3/4". | D36: 1 | E36: sistema | F36: 27922875 | G36: =ROUND(F36*0.1,0) -> 2792288 | H36: =D36*(F36+G36) -> 30715163 | I36: ~7 500 USD | J36: https://www.interroll.com/es/
B37: 4.4 | C37: Conveyor de triple cadena — salida de palets cargados L2 Cadenas reforzadas 3/4". | D37: 1 | E37: sistema | F37: 27922875 | G37: =ROUND(F37*0.1,0) -> 2792288 | H37: =D37*(F37+G37) -> 30715163 | I37: ~7 500 USD | J37: https://www.interroll.com/es/
B38: 4.5 | C38: Dispensador automático de palets vacíos + banda alimentadora L1 | D38: 1 | E38: sistema | F38: 22338300 | G38: =ROUND(F38*0.1,0) -> 2233830 | H38: =D38*(F38+G38) -> 24572130 | I38: ~6 000 USD | J38: Fabricación local / Interroll
B39: 4.6 | C39: Dispensador automático de palets vacíos + banda alimentadora L2 | D39: 1 | E39: sistema | F39: 22338300 | G39: =ROUND(F39*0.1,0) -> 2233830 | H39: =D39*(F39+G39) -> 24572130 | I39: ~6 000 USD | J39: Fabricación local / Interroll
B40: 4.7 | C40: Banda plana PVC — ingreso de láminas de cartón (slip-sheets) L1 Banda lisa de PVC desde el punto de carga externo hasta el interior de la celda L1. | D40: 1 | E40: sistema | F40: 13030675 | G40: =ROUND(F40*0.1,0) -> 1303068 | H40: =D40*(F40+G40) -> 14333743 | I40: ~3 500 USD | J40: Fabricación local / Interroll
...

Sheet OPEX_Beneficios
B1: OPEX ANUAL Y BENEFICIOS — CELDA ROBÓTICA DE PALETIZADO
B3: COSTOS OPERATIVOS ANUALES (OPEX)
B4: Concepto | C4: Costo Anual (COP) | D4: Referencia | E4: Nota / Base de Cálculo
B5: Mantenimiento preventivo anual (robots + envolvedoras) | C5: =ROUND((CAPEX!F4+CAPEX!F5+CAPEX!F6*2+CAPEX!F41+CAPEX!F42)*0.025,0) -> 18149869 | D5: Contrato ABB | E5: 2,5 % sobre precio robots, controladores, stretch wrapper y Clearpack / año
B6: Consumo energía eléctrica (2 robots + conveyors) | C6: =ROUND((Supuestos!C28+Supuestos!C29+Supuestos!C30+Supuestos!C33)*Supuestos!C31*Supuestos!C8*Supuestos!C32,0) -> 94170000 | D6: Cálculo Supuestos! | E6: Cálculo: (Pot. robot L1 + L2 + conveyors + Clearpack/stretch) × horas/día × días/año × tarifa kWh
B7: Licencias software anuales (Studio 5000, RobotStudio, FactoryTalk View) | C7: 18000000 | D7: Rockwell / ABB | E7: Renovación anual de licencias de programación y supervisión
B8: Repuestos consumibles y lubricantes (correas, filtros, grasa) | C8: 10000000 | D8: Stock mínimo | E8: Estimado sobre historial mantenimiento robots similares- celdas
B9: Supervisión técnica especializada (1 técnico robótica a tiempo parcial) | C9: 18000000 | D9: Perfil técnico SENA/Univ. | E9: ~$1,500,000 COP/mes × 12 meses
B10: Seguros maquinaria y responsabilidad civil | C10: =ROUND(CAPEX!H68*0.008,0) -> 12800970 | D10: Aseguradora | E10: Prima anual estimada 0,8 % sobre CAPEX subtotal (sin IVA)
B11: TOTAL OPEX ANUAL (Año 1) | C11: =C5+C6+C7+C8+C9+C10 -> 171120839
B14: BENEFICIOS / AHORROS ANUALES ESTIMADOS
B15: Concepto | C15: Valor Anual (COP) | D15: Referencia | E15: Base de Cálculo
B16: Reducción costo mano de obra (operadores paletizado suprimidos) | C16: =Supuestos!C49*Supuestos!C21*12 -> 5.4292062e+08 | D16: Cálculo Supuestos! | E16: Cálculo: Total Op. suprimidos (paletizado + empaque) × (Salario + Prestaciones) × 12 meses. Incluye los 8 operadores de paletizado + 9 operadores de empaque (3/turno × 3 turnos) reemplazados por la Clearpack EFK250L.
B17: Reducción tiempos de parada por lesiones/accidentes en paletizado | C17: 15000000 | D17: HSE interno | E17: Promedio 2 paradas/mes × 30 min × costo oportunidad
B18: Reducción pérdidas de producto por manejo manual deficiente | C18: 20000000 | D18: Control Calidad | E18: Reducción tasa daño 0.08% sobre producción anual
B19: Reducción horas extra (paletizado manual lento → cuellos de botella) | C19: 12000000 | D19: RRHH | E19: Estimado reducción 2 h extra/semana × 52 semanas
B20: Mejora en disponibilidad OEE (automatización elimina variabilidad humana) | C20: 10000000 | D20: Indicadores OEE | E20: Aumento estimado 1-2% OEE sobre línea
B21: Reducción ausentismo y gastos ARL (eliminación tarea ergonómicamente riesgosa) | C21: 7000000 | D21: ARL Sura / Positiva | E21: Reducción incidentes músculo-esqueléticos paletizado
B22: TOTAL BENEFICIOS ANUALES BRUTOS (Año 1) | C22: =C16+C17+C18+C19+C20+C21 -> 6.0692062e+08
B23: FLUJO NETO ANUAL (Beneficios − OPEX) | C23: =C22-C11 -> 4.3579978e+08
C24: =C23-C11 -> 2.6467894e+08

Sheet Flujo_de_Caja
B1: FLUJO DE CAJA — CELDA ROBÓTICA DE PALETIZADO (Horizonte 10 años)
B2: Concepto | C2: Año 0 | D2: Año 1 | E2: Año 2 | F2: Año 3 | G2: Año 4 | H2: Año 5 | I2: Año 6 | J2: Año 7 | K2: Año 8 | L2: Año 9 | M2: Año 10
B3: INVERSIÓN (CAPEX)
B4: CAPEX Total (con IVA) | C4: =-CAPEX!H70 -> -1.9041443e+09 | D4: =0 -> 0 | E4: =0 -> 0 | F4: =0 -> 0 | G4: =0 -> 0 | H4: =0 -> 0 | I4: =0 -> 0 | J4: =0 -> 0 | K4: =0 -> 0 | ... M4: =0 -> 0
B5: COSTOS OPERATIVOS (OPEX)
B6: Mantenimiento preventivo | C6: =0 -> 0 | D6: =OPEX_Beneficios!C5*((1+Supuestos!$C$14)^1) -> 19057362 | E6: =OPEX_Beneficios!C5*((1+Supuestos!$C$14)^2) -> 20010231 | F6: =OPEX_Beneficios!C5*((1+Supuestos!$C$14)^3) -> 21010742 | G6: =OPEX_Beneficios!C5*((1+Supuestos!$C$14)^4) -> 22061279 | H6: =OPEX_Beneficios!C5*((1+Supuestos!$C$14)^5) -> 23164343 | I6: =OPEX_Beneficios!C5*((1+Supuestos!$C$14)^6) -> 24322560 | J6: =OPEX_Beneficios!C5*((1+Supuestos!$C$14)^7) -> 25538688 | K6: =OPEX_Beneficios!C5*((1+Supuestos!$C$14)^8) -> 26815623 | L6: =OPEX_Beneficios!C5*((1+Supuestos!$C$14)^9) -> 28156404 | M6: =OPEX_Beneficios!C5*((1+Supuestos!$C$14)^10) -> 29564224
B7: Energía eléctrica | C7: =0 -> 0 | D7: =OPEX_Beneficios!C6*((1+Supuestos!$C$14)^1) -> 98878500 | E7: =OPEX_Beneficios!C6*((1+Supuestos!$C$14)^2) -> 103822425 | F7: =OPEX_Beneficios!C6*((1+Supuestos!$C$14)^3) -> 1.0901355e+08 | G7: =OPEX_Beneficios!C6*((1+Supuestos!$C$14)^4) -> 1.1446422e+08 | H7: =OPEX_Beneficios!C6*((1+Supuestos!$C$14)^5) -> 1.2018743e+08 | I7: =OPEX_Beneficios!C6*((1+Supuestos!$C$14)^6) -> 1.2619681e+08 | J7: =OPEX_Beneficios!C6*((1+Supuestos!$C$14)^7) -> 1.3250665e+08 | K7: =OPEX_Beneficios!C6*((1+Supuestos!$C$14)^8) -> 1.3913198e+08 | L7: =OPEX_Beneficios!C6*((1+Supuestos!$C$14)^9) -> 1.4608858e+08 | M7: =OPEX_Beneficios!C6*((1+Supuestos!$C$14)^10) -> 1.5339301e+08
B8: Licencias software | C8: =0 -> 0 | D8: =OPEX_Beneficios!C7*((1+Supuestos!$C$14)^1) -> 18900000 | E8: =OPEX_Beneficios!C7*((1+Supuestos!$C$14)^2) -> 19845000 | F8: =OPEX_Beneficios!C7*((1+Supuestos!$C$14)^3) -> 20837250 | G8: =OPEX_Beneficios!C7*((1+Supuestos!$C$14)^4) -> 21879112 | H8: =OPEX_Beneficios!C7*((1+Supuestos!$C$14)^5) -> 22973068 | I8: =OPEX_Beneficios!C7*((1+Supuestos!$C$14)^6) -> 24121722 | J8: =OPEX_Beneficios!C7*((1+Supuestos!$C$14)^7) -> 25327808 | K8: =OPEX_Beneficios!C7*((1+Supuestos!$C$14)^8) -> 26594198 | L8: =OPEX_Beneficios!C7*((1+Supuestos!$C$14)^9) -> 27923908 | M8: =OPEX_Beneficios!C7*((1+Supuestos!$C$14)^10) -> 29320103
B9: Repuestos y consumibles | C9: =0 -> 0 | D9: =OPEX_Beneficios!C8*((1+Supuestos!$C$14)^1) -> 10500000 | E9: =OPEX_Beneficios!C8*((1+Supuestos!$C$14)^2) -> 11025000 | F9: =OPEX_Beneficios!C8*((1+Supuestos!$C$14)^3) -> 11576250 | G9: =OPEX_Beneficios!C8*((1+Supuestos!$C$14)^4) -> 12155062 | H9: =OPEX_Beneficios!C8*((1+Supuestos!$C$14)^5) -> 12762816 | I9: =OPEX_Beneficios!C8*((1+Supuestos!$C$14)^6) -> 13400956 | J9: =OPEX_Beneficios!C8*((1+Supuestos!$C$14)^7) -> 14071004 | K9: =OPEX_Beneficios!C8*((1+Supuestos!$C$14)^8) -> 14774554 | L9: =OPEX_Beneficios!C8*((1+Supuestos!$C$14)^9) -> 15513282 | M9: =OPEX_Beneficios!C8*((1+Supuestos!$C$14)^10) -> 16288946
B10: Supervisión técnica | C10: =0 -> 0 | D10: =OPEX_Beneficios!C9*((1+Supuestos!$C$14)^1) -> 18900000 | E10: =OPEX_Beneficios!C9*((1+Supuestos!$C$14)^2) -> 19845000 | F10: =OPEX_Beneficios!C9*((1+Supuestos!$C$14)^3) -> 20837250 | G10: =OPEX_Beneficios!C9*((1+Supuestos!$C$14)^4) -> 21879112 | H10: =OPEX_Beneficios!C9*((1+Supuestos!$C$14)^5) -> 22973068 | I10: =OPEX_Beneficios!C9*((1+Supuestos!$C$14)^6) -> 24121722 | J10: =OPEX_Beneficios!C9*((1+Supuestos!$C$14)^7) -> 25327808 | K10: =OPEX_Beneficios!C9*((1+Supuestos!$C$14)^8) -> 26594198 | L10: =OPEX_Beneficios!C9*((1+Supuestos!$C$14)^9) -> 27923908 | M10: =OPEX_Beneficios!C9*((1+Supuestos!$C$14)^10) -> 29320103
B11: Seguros maquinaria | C11: =0 -> 0 | D11: =OPEX_Beneficios!C10*((1+Supuestos!$C$14)^1) -> 13441018 | E11: =OPEX_Beneficios!C10*((1+Supuestos!$C$14)^2) -> 14113069 | F11: =OPEX_Beneficios!C10*((1+Supuestos!$C$14)^3) -> 14818723 | G11: =OPEX_Beneficios!C10*((1+Supuestos!$C$14)^4) -> 15559659 | H11: =OPEX_Beneficios!C10*((1+Supuestos!$C$14)^5) -> 16337642 | I11: =OPEX_Beneficios!C10*((1+Supuestos!$C$14)^6) -> 17154524 | J11: =OPEX_Beneficios!C10*((1+Supuestos!$C$14)^7) -> 18012250 | K11: =OPEX_Beneficios!C10*((1+Supuestos!$C$14)^8) -> 18912863 | L11: =OPEX_Beneficios!C10*((1+Supuestos!$C$14)^9) -> 19858506 | M11: =OPEX_Beneficios!C10*((1+Supuestos!$C$14)^10) -> 20851431
B12: TOTAL OPEX | C12: =SUM(C6:C11) -> 0 | D12: =SUM(D6:D11) -> 1.7967688e+08 | E12: =SUM(E6:E11) -> 1.8866072e+08 | F12: =SUM(F6:F11) -> 1.9809376e+08 | G12: =SUM(G6:G11) -> 2.0799845e+08 | H12: =SUM(H6:H11) -> 2.1839837e+08 | I12: =SUM(I6:I11) -> 2.2931829e+08 | J12: =SUM(J6:J11) -> 2.407842e+08 | ... M12: =SUM(M6:M11) -> 2.7873782e+08
B13: BENEFICIOS / AHORROS
B14: Reducción MO paletizado | C14: =0 -> 0 | D14: =OPEX_Beneficios!C16*((1+Supuestos!$C$14)^1) -> 5.7006665e+08 | E14: =OPEX_Beneficios!C16*((1+Supuestos!$C$14)^2) -> 5.9856999e+08 | F14: =OPEX_Beneficios!C16*((1+Supuestos!$C$14)^3) -> 6.2849849e+08 | G14: =OPEX_Beneficios!C16*((1+Supuestos!$C$14)^4) -> 6.5992341e+08 | H14: =OPEX_Beneficios!C16*((1+Supuestos!$C$14)^5) -> 6.9291958e+08 | I14: =OPEX_Beneficios!C16*((1+Supuestos!$C$14)^6) -> 7.2756556e+08 | J14: =OPEX_Beneficios!C16*((1+Supuestos!$C$14)^7) -> 7.6394384e+08 | K14: =OPEX_Beneficios!C16*((1+Supuestos!$C$14)^8) -> 8.0214103e+08 | L14: =OPEX_Beneficios!C16*((1+Supuestos!$C$14)^9) -> 8.4224808e+08 | M14: =OPEX_Beneficios!C16*((1+Supuestos!$C$14)^10) -> 8.8436048e+08
B15: Reducción tiempos parada | C15: =0 -> 0 | D15: =OPEX_Beneficios!C17*((1+Supuestos!$C$15)^1) -> 15450000 | E15: =OPEX_Beneficios!C17*((1+Supuestos!$C$15)^2) -> 15913500 | F15: =OPEX_Beneficios!C17*((1+Supuestos!$C$15)^3) -> 16390905 | G15: =OPEX_Beneficios!C17*((1+Supuestos!$C$15)^4) -> 16882632 | H15: =OPEX_Beneficios!C17*((1+Supuestos!$C$15)^5) -> 17389111 | I15: =OPEX_Beneficios!C17*((1+Supuestos!$C$15)^6) -> 17910784 | J15: =OPEX_Beneficios!C17*((1+Supuestos!$C$15)^7) -> 18448108 | K15: =OPEX_Beneficios!C17*((1+Supuestos!$C$15)^8) -> 19001551 | L15: =OPEX_Beneficios!C17*((1+Supuestos!$C$15)^9) -> 19571598 | M15: =OPEX_Beneficios!C17*((1+Supuestos!$C$15)^10) -> 20158746
B16: Reducción pérdidas producto | C16: =0 -> 0 | D16: =OPEX_Beneficios!C18*((1+Supuestos!$C$15)^1) -> 20600000 | E16: =OPEX_Beneficios!C18*((1+Supuestos!$C$15)^2) -> 21218000 | F16: =OPEX_Beneficios!C18*((1+Supuestos!$C$15)^3) -> 21854540 | G16: =OPEX_Beneficios!C18*((1+Supuestos!$C$15)^4) -> 22510176 | H16: =OPEX_Beneficios!C18*((1+Supuestos!$C$15)^5) -> 23185481 | I16: =OPEX_Beneficios!C18*((1+Supuestos!$C$15)^6) -> 23881046 | J16: =OPEX_Beneficios!C18*((1+Supuestos!$C$15)^7) -> 24597477 | K16: =OPEX_Beneficios!C18*((1+Supuestos!$C$15)^8) -> 25335402 | L16: =OPEX_Beneficios!C18*((1+Supuestos!$C$15)^9) -> 26095464 | M16: =OPEX_Beneficios!C18*((1+Supuestos!$C$15)^10) -> 26878328
B17: Reducción horas extra | C17: =0 -> 0 | D17: =OPEX_Beneficios!C19*((1+Supuestos!$C$14)^1) -> 12600000 | E17: =OPEX_Beneficios!C19*((1+Supuestos!$C$14)^2) -> 13230000 | F17: =OPEX_Beneficios!C19*((1+Supuestos!$C$14)^3) -> 13891500 | G17: =OPEX_Beneficios!C19*((1+Supuestos!$C$14)^4) -> 14586075 | H17: =OPEX_Beneficios!C19*((1+Supuestos!$C$14)^5) -> 15315379 | I17: =OPEX_Beneficios!C19*((1+Supuestos!$C$14)^6) -> 16081148 | J17: =OPEX_Beneficios!C19*((1+Supuestos!$C$14)^7) -> 16885205 | K17: =OPEX_Beneficios!C19*((1+Supuestos!$C$14)^8) -> 17729465 | L17: =OPEX_Beneficios!C19*((1+Supuestos!$C$14)^9) -> 18615939 | M17: =OPEX_Beneficios!C19*((1+Supuestos!$C$14)^10) -> 19546736
B18: Mejora OEE | C18: =0 -> 0 | D18: =OPEX_Beneficios!C20*((1+Supuestos!$C$15)^1) -> 10300000 | E18: =OPEX_Beneficios!C20*((1+Supuestos!$C$15)^2) -> 10609000 | F18: =OPEX_Beneficios!C20*((1+Supuestos!$C$15)^3) -> 10927270 | G18: =OPEX_Beneficios!C20*((1+Supuestos!$C$15)^4) -> 11255088 | H18: =OPEX_Beneficios!C20*((1+Supuestos!$C$15)^5) -> 11592741 | I18: =OPEX_Beneficios!C20*((1+Supuestos!$C$15)^6) -> 11940523 | J18: =OPEX_Beneficios!C20*((1+Supuestos!$C$15)^7) -> 12298739 | K18: =OPEX_Beneficios!C20*((1+Supuestos!$C$15)^8) -> 12667701 | L18: =OPEX_Beneficios!C20*((1+Supuestos!$C$15)^9) -> 13047732 | M18: =OPEX_Beneficios!C20*((1+Supuestos!$C$15)^10) -> 13439164
B19: Reducción ausentismo/ARL | C19: =0 -> 0 | D19: =OPEX_Beneficios!C21*((1+Supuestos!$C$14)^1) -> 7350000 | E19: =OPEX_Beneficios!C21*((1+Supuestos!$C$14)^2) -> 7717500 | F19: =OPEX_Beneficios!C21*((1+Supuestos!$C$14)^3) -> 8103375 | G19: =OPEX_Beneficios!C21*((1+Supuestos!$C$14)^4) -> 8508543.8 | H19: =OPEX_Beneficios!C21*((1+Supuestos!$C$14)^5) -> 8933970.9 | I19: =OPEX_Beneficios!C21*((1+Supuestos!$C$14)^6) -> 9380669.5 | J19: =OPEX_Beneficios!C21*((1+Supuestos!$C$14)^7) -> 9849703 | K19: =OPEX_Beneficios!C21*((1+Supuestos!$C$14)^8) -> 10342188 | L19: =OPEX_Beneficios!C21*((1+Supuestos!$C$14)^9) -> 10859298 | M19: =OPEX_Beneficios!C21*((1+Supuestos!$C$14)^10) -> 11402262
B20: TOTAL BENEFICIOS | C20: =SUM(C14:C19) -> 0 | D20: =SUM(D14:D19) -> 6.3636665e+08 | E20: =SUM(E14:E19) -> 6.6725799e+08 | F20: =SUM(F14:F19) -> 6.9966608e+08 | G20: =SUM(G14:G19) -> 7.3366592e+08 | H20: =SUM(H14:H19) -> 7.6933626e+08 | I20: =SUM(I14:I19) -> 8.0675973e+08 | J20: =SUM(J14:J19) -> 8.4602307e+08 | ... M20: =SUM(M14:M19) -> 9.7578572e+08
B21: FLUJO NETO DEL PERÍODO | C21: =C4 -> -1.9041443e+09 | D21: =D20-D12+D4 -> 4.5668977e+08 | E21: =E20-E12+E4 -> 4.7859726e+08 | F21: =F20-F12+F4 -> 5.0157231e+08 | G21: =G20-G12+G4 -> 5.2566748e+08 | H21: =H20-H12+H4 -> 5.5093789e+08 | I21: =I20-I12+I4 -> 5.7744144e+08 | J21: =J20-J12+J4 -> 6.0523886e+08 | K21: =K20-K12+K4 -> 6.3439392e+08 | ... M21: =M20-M12+M4 -> 6.970479e+08
B22: FLUJO ACUMULADO | C22: =C21 -> -1.9041443e+09 | D22: =D21+C22 -> -1.4474545e+09 | E22: =E21+D22 -> -9.6885729e+08 | F22: =F21+E22 -> -4.6728497e+08 | G22: =G21+F22 -> 58382504 | H22: =H21+G22 -> 6.093204e+08 | I22: =I21+H22 -> 1.1867618e+09 | J22: =J21+I22 -> 1.7920007e+09 | K22: =K21+J22 -> 2.4263946e+09 | ... M22: =M21+L22 -> 3.788416e+09
B24: FLUJO DESCONTADO (WACC = 12%)
B25: FLUJO DESCONTADO (WACC = 12 %)
C26: =C21 -> -1.9041443e+09 | D26: =D21/((1+Supuestos!$C$13)^1) -> 4.0775873e+08 | E26: =E21/((1+Supuestos!$C$13)^2) -> 3.8153481e+08 | F26: =F21/((1+Supuestos!$C$13)^3) -> 3.5700927e+08 | G26: =G21/((1+Supuestos!$C$13)^4) -> 3.3407118e+08 | H26: =H21/((1+Supuestos!$C$13)^5) -> 3.1261696e+08 | I26: =I21/((1+Supuestos!$C$13)^6) -> 2.925498e+08 | J26: =J21/((1+Supuestos!$C$13)^7) -> 2.7377933e+08 | K26: =K21/((1+Supuestos!$C$13)^8) -> 2.5622106e+08 | L26: =L21/((1+Supuestos!$C$13)^9) -> 2.3979612e+08 | M26: =M21/((1+Supuestos!$C$13)^10) -> 2.2443077e+08

Sheet Indicadores
B1: INDICADORES FINANCIEROS — CELDA ROBÓTICA DE PALETIZADO
B3: INDICADORES CLAVE DE RENTABILIDAD
B4: Indicador | D4: Valor | E4: Unidad | F4: Interpretación
B5: VPN — Valor Presente Neto | C5: → | D5: {=NPV(Supuestos!C13,Flujo_de_Caja!D21:M21)+Flujo_de_Caja!C21} -> 1.1756237e+09 | E5: COP | F5: VPN > 0: el proyecto genera valor. VPN < 0: no rentable al WACC dado.
B6: TIR — Tasa Interna de Retorno | C6: → | D6: =IRR(Flujo_de_Caja!C21:M21) -> 0.24504193 | E6: % | F6: TIR > WACC (12%): proyecto viable. TIR < WACC: rechazar.
B7: Payback simple | C7: → | D7: =CAPEX!H70/OPEX_Beneficios!C23 -> 4.3693099 | E7: años | F7: Período de recuperación sin descontar la inversión.
B8: ROI — Retorno sobre Inversión (10 años) | C8: → | D8: =(OPEX_Beneficios!C23*10-CAPEX!H70)/CAPEX!H70 -> 1.2886909 | E8: % | F8: Retorno total sobre el CAPEX a 10 años (sin descontar).
B9: Flujo Neto Anual (Año 1) | C9: → | D9: =OPEX_Beneficios!C23 -> 4.3579978e+08 | E9: COP/año | F9: Beneficios anuales brutos menos OPEX del primer año.
B10: CAPEX Total (con IVA) | C10: → | D10: =CAPEX!H70 -> 1.9041443e+09 | E10: COP | F10: Inversión inicial total incluyendo IVA (19%).
B11: OPEX Anual (Año 1) | C11: → | D11: =OPEX_Beneficios!C11 -> 171120839 | E11: COP/año | F11: Costos operativos del primer año de operación.
B12: Beneficios Brutos Anuales (Año 1) | C12: → | D12: =OPEX_Beneficios!C22 -> 6.0692062e+08 | E12: COP/año | F12: Total ahorros y beneficios cuantificables del primer año.
B15: ANÁLISIS DE SENSIBILIDAD — WACC vs VPN
B16: Tasa de descuento | D16: VPN Resultante (COP) | F16: Interpretación
B17: 0.06 | C17: → | D17: {=NPV(Indicadores!B17,Flujo_de_Caja!D21:M21)+Flujo_de_Caja!C21} -> 2.1922886e+09 | F17: Muy favorable
B18: 0.08 | C18: → | D18: {=NPV(Indicadores!B18,Flujo_de_Caja!D21:M21)+Flujo_de_Caja!C21} -> 1.803842e+09 | F18: Favorable
B19: 0.1 | C19: → | D19: {=NPV(Indicadores!B19,Flujo_de_Caja!D21:M21)+Flujo_de_Caja!C21} -> 1.467768e+09 | F19: Bueno
B20: 0.12 | C20: → | D20: {=NPV(Indicadores!B20,Flujo_de_Caja!D21:M21)+Flujo_de_Caja!C21} -> 1.1756237e+09 | F20: Base (WACC) ✔ BASE
B21: 0.14 | C21: → | D21: {=NPV(Indicadores!B21,Flujo_de_Caja!D21:M21)+Flujo_de_Caja!C21} -> 9.2050216e+08 | F21: Ajustado
B22: 0.16 | C22: → | D22: {=NPV(Indicadores!B22,Flujo_de_Caja!D21:M21)+Flujo_de_Caja!C21} -> 6.9672595e+08 | F22: Exigente
B23: 0.18 | C23: → | D23: {=NPV(Indicadores!B23,Flujo_de_Caja!D21:M21)+Flujo_de_Caja!C21} -> 4.9960642e+08 | F23: Muy exigente
